<mujoco model="onshape">
	<compiler angle="radian" meshdir="../meshes/" />
	<size njmax="500" nconmax="100"  nuser_actuator='1' />
	<option gravity="0 0 -9.806" timestep="0.001" iterations="50" tolerance="1e-10" solver="Newton" jacobian="dense" cone="elliptic" impratio="100" />
	<default>
		<geom contype="1" conaffinity="1" friction="0.6 0.3 0.3" rgba="0.5 0.6 0.7 1" margin="0.001" group="0" />
		<light castshadow="false" diffuse="1 1 1" />
		<motor ctrlrange="-7 7" ctrllimited="true" />
		<camera fovy="60" />
		<joint damping="0.01" armature="0.01" />
	</default>
	<asset>
		<mesh name="finalhead" file="finalhead.stl" />
		<mesh name="finalrod" file="finalrod.stl" />
		<mesh name="finalcoupling" file="finalcoupling.stl" />
		<mesh name="finalend" file="finalend.stl" />
	</asset>
	<asset>
		<texture type="skybox" builtin="gradient" rgb1="1.0 1.0 1.0" rgb2="1.0 1.0 1.0" width="512" height="512" />
		<texture name="plane" type="2d" builtin="flat" rgb1="1 1 1" rgb2="1 1 1" width="512" height="512" mark="cross" markrgb="0 0 0" />
		<material name="plane" reflectance="0.0" texture="plane" texrepeat="3 3" texuniform="true" />
	</asset>
	<worldbody>
		<light directional="true" diffuse=".8 .8 .8" pos="0 0 10" dir="0 0 -10" />
		<camera name="track" mode="trackcom" pos="0 -1.3 1.6" xyaxes="1 0 0 0 0.707 0.707" />
		<geom name="floor" type="plane" conaffinity="1" condim="3" contype="1" rgba="0.5 0.9 0.9 0.1" material="plane" pos="0 0 0" size="0 0 1" />
		<body name="finalhead" pos="0 0 0">
			<inertial pos="0.000501801 0.0148621 0.0426872" quat="0.43159 0.556763 -0.57214 0.420001" mass="0.246213" diaginertia="0.000196123 0.000190987 9.74484e-05" />
			<joint name="floating_base" type="free" />
			<geom pos="0.000743331 0.0237264 0.0388336" quat="0.999907 0 0 -0.0136159" type="mesh" contype="0" conaffinity="0" group="1" rgba="0.596078 0.176471 0.0509804 1" mesh="finalhead" />
			<geom pos="0.000743331 0.0237264 0.0388336" quat="0.999907 0 0 -0.0136159" type="mesh" rgba="0.596078 0.176471 0.0509804 1" mesh="finalhead" />
			<geom pos="0.00128792 0.043719 0.0086617" quat="0.999907 0 0 -0.0136159" type="mesh" contype="0" conaffinity="0" group="1" rgba="1 0.996078 0.968627 1" mesh="finalrod" />
			<geom pos="0.00128792 0.043719 0.0086617" quat="0.999907 0 0 -0.0136159" type="mesh" rgba="1 0.996078 0.968627 1" mesh="finalrod" />
			<body name="finalcoupling" pos="0.00128792 0.043719 0.0393336" quat="0.708112 0 0 0.7061">
				<inertial pos="0.0321744 -0.00447826 -0.00399057" quat="-0.0371197 0.601631 -0.15798 0.782116" mass="0.211217" diaginertia="0.000206229 0.000199224 7.11662e-05" />
				<joint name="joint1" pos="0 0 0" axis="0 0 1" />
				<geom pos="0.02 0 0.0005" quat="0.499998 0.5 0.5 -0.500002" type="mesh" contype="0" conaffinity="0" group="1" rgba="0.372549 0.533333 1 1" mesh="finalcoupling" />
				<geom pos="0.02 0 0.0005" quat="0.499998 0.5 0.5 -0.500002" type="mesh" rgba="0.372549 0.533333 1 1" mesh="finalcoupling" />
				<geom pos="0.06 0.0301709 0.0005" quat="0.707105 0.707108 0 0" type="mesh" contype="0" conaffinity="0" group="1" rgba="1 0.996078 0.968627 1" mesh="finalrod" />
				<geom pos="0.06 0.0301709 0.0005" quat="0.707105 0.707108 0 0" type="mesh" rgba="1 0.996078 0.968627 1" mesh="finalrod" />
				<body name="finalcoupling_2" pos="0.06 -0.0005 0.0005" quat="0.499998 0.5 0.5 -0.500002">
					<inertial pos="0.00484149 0.03 -0.00434156" quat="0.599413 0.68929 -0.374902 0.158217" mass="0.195908" diaginertia="0.00018962 0.000185433 6.4679e-05" />
					<joint name="joint2" pos="0 0 0" axis="0 0 1" />
					<geom pos="0 0.04 0.0005" quat="1.32679e-06 -1 0 0" type="mesh" contype="0" conaffinity="0" group="1" rgba="0.372549 0.533333 1 1" mesh="finalcoupling" />
					<geom pos="0 0.04 0.0005" quat="1.32679e-06 -1 0 0" type="mesh" rgba="0.372549 0.533333 1 1" mesh="finalcoupling" />
					<body name="finalcoupling_3" pos="0.0005 0.06 0.0005" quat="0.707105 0 0.707108 0">
						<inertial pos="0.00449058 0.0278256 -0.00397826" quat="0.631445 0.752315 -0.18774 0.00727006" mass="0.211217" diaginertia="0.000206231 0.000199225 7.11641e-05" />
						<joint name="joint3" pos="0 0 0" axis="0 0 1" />
						<geom pos="0 0 0.0306709" quat="1.76038e-12 1.32679e-06 -1 -1.32679e-06" type="mesh" contype="0" conaffinity="0" group="1" rgba="1 0.996078 0.968627 1" mesh="finalrod" />
						<geom pos="0 0 0.0306709" quat="1.76038e-12 1.32679e-06 -1 -1.32679e-06" type="mesh" rgba="1 0.996078 0.968627 1" mesh="finalrod" />
						<geom pos="0 0.04 0.0005" quat="1.32679e-06 1 0 0" type="mesh" contype="0" conaffinity="0" group="1" rgba="0.372549 0.533333 1 1" mesh="finalcoupling" />
						<geom pos="0 0.04 0.0005" quat="1.32679e-06 1 0 0" type="mesh" rgba="0.372549 0.533333 1 1" mesh="finalcoupling" />
						<body name="finalcoupling_4" pos="0.0005 0.06 0.0005" quat="0.499998 0.5 0.500002 0.5">
							<inertial pos="0.03 -0.00417561 -0.00367555" quat="0.738899 0.305687 0.554955 0.229364" mass="0.226526" diaginertia="0.000221478 0.000218195 7.76443e-05" />
							<joint name="joint4" pos="0 0 0" axis="0 0 1" />
							<geom pos="0.02 0 0.0005" quat="0.499998 0.5 0.5 -0.500002" type="mesh" contype="0" conaffinity="0" group="1" rgba="0.372549 0.533333 1 1" mesh="finalcoupling" />
							<geom pos="0.02 0 0.0005" quat="0.499998 0.5 0.5 -0.500002" type="mesh" rgba="0.372549 0.533333 1 1" mesh="finalcoupling" />
							<geom pos="0 0 0.0306709" quat="9.38184e-07 -0.707105 -0.707108 9.38187e-07" type="mesh" contype="0" conaffinity="0" group="1" rgba="1 0.996078 0.968627 1" mesh="finalrod" />
							<geom pos="0 0 0.0306709" quat="9.38184e-07 -0.707105 -0.707108 9.38187e-07" type="mesh" rgba="1 0.996078 0.968627 1" mesh="finalrod" />
							<geom pos="0.06 0.0301709 0.0005" quat="0.499998 0.5 0.5 -0.500002" type="mesh" contype="0" conaffinity="0" group="1" rgba="1 0.996078 0.968627 1" mesh="finalrod" />
							<geom pos="0.06 0.0301709 0.0005" quat="0.499998 0.5 0.5 -0.500002" type="mesh" rgba="1 0.996078 0.968627 1" mesh="finalrod" />
							<body name="finalcoupling_5" pos="0.06 -0.0005 0.0005" quat="0.707105 0.707108 0 0">
								<inertial pos="0.0321744 -0.00447826 -0.00399057" quat="-0.0371197 0.601631 -0.15798 0.782116" mass="0.211217" diaginertia="0.000206229 0.000199224 7.11662e-05" />
								<joint name="joint5" pos="0 0 0" axis="0 0 1" />
								<geom pos="0.02 0 0.0005" quat="0.499998 0.5 0.5 -0.500002" type="mesh" contype="0" conaffinity="0" group="1" rgba="0.372549 0.533333 1 1" mesh="finalcoupling" />
								<geom pos="0.02 0 0.0005" quat="0.499998 0.5 0.5 -0.500002" type="mesh" rgba="0.372549 0.533333 1 1" mesh="finalcoupling" />
								<geom pos="0.06 0.0301709 0.0005" quat="0.707105 0.707108 0 0" type="mesh" contype="0" conaffinity="0" group="1" rgba="1 0.996078 0.968627 1" mesh="finalrod" />
								<geom pos="0.06 0.0301709 0.0005" quat="0.707105 0.707108 0 0" type="mesh" rgba="1 0.996078 0.968627 1" mesh="finalrod" />
								<body name="finalcoupling_6" pos="0.06 -0.0005 0.0005" quat="0.499998 0.5 0.5 -0.500002">
									<inertial pos="0.00447731 0.0321744 -0.00399064" quat="0.537149 0.579359 -0.526716 0.313663" mass="0.211217" diaginertia="0.000206226 0.000199229 7.11677e-05" />
									<joint name="joint6" pos="0 0 0" axis="0 0 1" />
									<geom pos="0.029817 0.06 0.0005" quat="0.707105 0 -0.707108 0" type="mesh" contype="0" conaffinity="0" group="1" rgba="1 0.996078 0.968627 1" mesh="finalrod" />
									<geom pos="0.029817 0.06 0.0005" quat="0.707105 0 -0.707108 0" type="mesh" rgba="1 0.996078 0.968627 1" mesh="finalrod" />
									<geom pos="0 0.04 0.0005" quat="1.32679e-06 -1 0 0" type="mesh" contype="0" conaffinity="0" group="1" rgba="0.372549 0.533333 1 1" mesh="finalcoupling" />
									<geom pos="0 0.04 0.0005" quat="1.32679e-06 -1 0 0" type="mesh" rgba="0.372549 0.533333 1 1" mesh="finalcoupling" />
									<body name="finalcoupling_7" pos="0.0005 0.06 0.0005" quat="0.499998 0.5 0.500002 0.5">
										<inertial pos="0.0321744 -0.00447737 -0.00399057" quat="-0.0370576 0.601648 -0.15791 0.782119" mass="0.211217" diaginertia="0.00020623 0.000199223 7.11701e-05" />
										<joint name="joint7" pos="0 0 0" axis="0 0 1" />
										<geom pos="0.02 0 0.0005" quat="0.499998 0.5 0.5 -0.500002" type="mesh" contype="0" conaffinity="0" group="1" rgba="0.372549 0.533333 1 1" mesh="finalcoupling" />
										<geom pos="0.02 0 0.0005" quat="0.499998 0.5 0.5 -0.500002" type="mesh" rgba="0.372549 0.533333 1 1" mesh="finalcoupling" />
										<geom pos="0.06 -0.029817 0.0005" quat="9.38184e-07 9.38187e-07 0.707108 0.707105" type="mesh" contype="0" conaffinity="0" group="1" rgba="1 0.996078 0.968627 1" mesh="finalrod" />
										<geom pos="0.06 -0.029817 0.0005" quat="9.38184e-07 9.38187e-07 0.707108 0.707105" type="mesh" rgba="1 0.996078 0.968627 1" mesh="finalrod" />
										<body name="finalcoupling_8" pos="0.06 -0.0005 0.0005" quat="0.499998 0.5 0.5 -0.500002">
											<inertial pos="0.00484149 0.03 -0.00434156" quat="0.599413 0.68929 -0.374902 0.158217" mass="0.195908" diaginertia="0.00018962 0.000185433 6.4679e-05" />
											<joint name="joint8" pos="0 0 0" axis="0 0 1" />
											<geom pos="0 0.04 0.0005" quat="1.32679e-06 1 0 0" type="mesh" contype="0" conaffinity="0" group="1" rgba="0.372549 0.533333 1 1" mesh="finalcoupling" />
											<geom pos="0 0.04 0.0005" quat="1.32679e-06 1 0 0" type="mesh" rgba="0.372549 0.533333 1 1" mesh="finalcoupling" />
											<body name="finalcoupling_9" pos="0.0005 0.06 0.0005" quat="0.707105 0 0.707108 0">
												<inertial pos="0.00417472 0.03 -0.00367478" quat="0.608797 0.685139 -0.359385 0.175478" mass="0.226526" diaginertia="0.000221475 0.000218193 7.7654e-05" />
												<joint name="joint9" pos="0 0 0" axis="0 0 1" />
												<geom pos="0.029817 0.06 0.0005" quat="0.499998 0.5 -0.500002 -0.5" type="mesh" contype="0" conaffinity="0" group="1" rgba="1 0.996078 0.968627 1" mesh="finalrod" />
												<geom pos="0.029817 0.06 0.0005" quat="0.499998 0.5 -0.500002 -0.5" type="mesh" rgba="1 0.996078 0.968627 1" mesh="finalrod" />
												<geom pos="0 0.04 0.0005" quat="1.32679e-06 1 0 0" type="mesh" contype="0" conaffinity="0" group="1" rgba="0.372549 0.533333 1 1" mesh="finalcoupling" />
												<geom pos="0 0.04 0.0005" quat="1.32679e-06 1 0 0" type="mesh" rgba="0.372549 0.533333 1 1" mesh="finalcoupling" />
												<geom pos="0 0 -0.029317" type="mesh" contype="0" conaffinity="0" group="1" rgba="1 0.996078 0.968627 1" mesh="finalrod" />
												<geom pos="0 0 -0.029317" type="mesh" rgba="1 0.996078 0.968627 1" mesh="finalrod" />
												<body name="finalcoupling_10" pos="0.0005 0.06 0.0005" quat="0.499998 0.5 0.500002 0.5">
													<inertial pos="0.0321744 -0.00447737 -0.00399058" quat="-0.0370073 0.601663 -0.15787 0.782119" mass="0.211217" diaginertia="0.000206233 0.000199223 7.11679e-05" />
													<joint name="joint10" pos="0 0 0" axis="0 0 1" />
													<geom pos="0.06 -0.029817 0.0005" quat="0.499998 -0.5 -0.5 -0.500002" type="mesh" contype="0" conaffinity="0" group="1" rgba="1 0.996078 0.968627 1" mesh="finalrod" />
													<geom pos="0.06 -0.029817 0.0005" quat="0.499998 -0.5 -0.5 -0.500002" type="mesh" rgba="1 0.996078 0.968627 1" mesh="finalrod" />
													<geom pos="0.02 0 0.0005" quat="0.499998 0.5 0.5 -0.500002" type="mesh" contype="0" conaffinity="0" group="1" rgba="0.372549 0.533333 1 1" mesh="finalcoupling" />
													<geom pos="0.02 0 0.0005" quat="0.499998 0.5 0.5 -0.500002" type="mesh" rgba="0.372549 0.533333 1 1" mesh="finalcoupling" />
													<body name="finalcoupling_11" pos="0.06 -0.0005 0.0005" quat="0.499998 0.5 0.5 -0.500002">
														<inertial pos="0.00484149 0.03 -0.00434156" quat="0.599413 0.68929 -0.374902 0.158217" mass="0.195908" diaginertia="0.00018962 0.000185433 6.4679e-05" />
														<joint name="joint11" pos="0 0 0" axis="0 0 1" />
														<geom pos="0 0.04 0.0005" quat="1.32679e-06 -1 0 0" type="mesh" contype="0" conaffinity="0" group="1" rgba="0.372549 0.533333 1 1" mesh="finalcoupling" />
														<geom pos="0 0.04 0.0005" quat="1.32679e-06 -1 0 0" type="mesh" rgba="0.372549 0.533333 1 1" mesh="finalcoupling" />
														<body name="finalcoupling_12" pos="0.0005 0.06 0.0005" quat="0.707105 0 0.707108 0">
															<inertial pos="0.00417555 0.03 -0.00367478" quat="0.608818 0.685167 -0.359332 0.175405" mass="0.226526" diaginertia="0.000221476 0.000218193 7.76526e-05" />
															<joint name="joint12" pos="0 0 0" axis="0 0 1" />
															<geom pos="0 0.04 0.0005" quat="1.32679e-06 -1 0 0" type="mesh" contype="0" conaffinity="0" group="1" rgba="0.372549 0.533333 1 1" mesh="finalcoupling" />
															<geom pos="0 0.04 0.0005" quat="1.32679e-06 -1 0 0" type="mesh" rgba="0.372549 0.533333 1 1" mesh="finalcoupling" />
															<geom pos="-0.0301709 0.06 0.0005" quat="0.499998 -0.5 0.500002 -0.5" type="mesh" contype="0" conaffinity="0" group="1" rgba="1 0.996078 0.968627 1" mesh="finalrod" />
															<geom pos="-0.0301709 0.06 0.0005" quat="0.499998 -0.5 0.500002 -0.5" type="mesh" rgba="1 0.996078 0.968627 1" mesh="finalrod" />
															<geom pos="0 0 -0.029317" quat="0.707105 0 0 -0.707108" type="mesh" contype="0" conaffinity="0" group="1" rgba="1 0.996078 0.968627 1" mesh="finalrod" />
															<geom pos="0 0 -0.029317" quat="0.707105 0 0 -0.707108" type="mesh" rgba="1 0.996078 0.968627 1" mesh="finalrod" />
															<body name="finalcoupling_13" pos="0.0005 0.06 0.0005" quat="0.707105 0 0.707108 0">
																<inertial pos="0.00447731 0.0321744 -0.00399064" quat="0.537162 0.579384 -0.526692 0.313635" mass="0.211217" diaginertia="0.000206225 0.000199228 7.117e-05" />
																<joint name="joint13" pos="0 0 0" axis="0 0 1" />
																<geom pos="0.029817 0.06 0.0005" quat="0.499998 0.5 -0.500002 -0.5" type="mesh" contype="0" conaffinity="0" group="1" rgba="1 0.996078 0.968627 1" mesh="finalrod" />
																<geom pos="0.029817 0.06 0.0005" quat="0.499998 0.5 -0.500002 -0.5" type="mesh" rgba="1 0.996078 0.968627 1" mesh="finalrod" />
																<geom pos="0 0.04 0.0005" quat="1.32679e-06 -1 0 0" type="mesh" contype="0" conaffinity="0" group="1" rgba="0.372549 0.533333 1 1" mesh="finalcoupling" />
																<geom pos="0 0.04 0.0005" quat="1.32679e-06 -1 0 0" type="mesh" rgba="0.372549 0.533333 1 1" mesh="finalcoupling" />
																<body name="finalcoupling_14" pos="0.0005 0.06 0.0005" quat="0.499998 0.5 0.500002 0.5">
																	<inertial pos="0.0321744 -0.00447826 -0.00399058" quat="-0.0370699 0.601645 -0.15794 0.782115" mass="0.211217" diaginertia="0.000206231 0.000199225 7.11641e-05" />
																	<joint name="joint14" pos="0 0 0" axis="0 0 1" />
																	<geom pos="0.06 0.0301709 0.0005" quat="0.499998 0.5 -0.5 0.500002" type="mesh" contype="0" conaffinity="0" group="1" rgba="1 0.996078 0.968627 1" mesh="finalrod" />
																	<geom pos="0.06 0.0301709 0.0005" quat="0.499998 0.5 -0.5 0.500002" type="mesh" rgba="1 0.996078 0.968627 1" mesh="finalrod" />
																	<geom pos="0.02 0 0.0005" quat="0.499998 0.5 0.5 -0.500002" type="mesh" contype="0" conaffinity="0" group="1" rgba="0.372549 0.533333 1 1" mesh="finalcoupling" />
																	<geom pos="0.02 0 0.0005" quat="0.499998 0.5 0.5 -0.500002" type="mesh" rgba="0.372549 0.533333 1 1" mesh="finalcoupling" />
																	<body name="finalcoupling_15" pos="0.06 -0.0005 0.0005" quat="0.499998 0.5 0.5 -0.500002">
																		<inertial pos="0.00484149 0.03 -0.00434156" quat="0.599413 0.68929 -0.374902 0.158217" mass="0.195908" diaginertia="0.00018962 0.000185433 6.4679e-05" />
																		<joint name="joint15" pos="0 0 0" axis="0 0 1" />
																		<geom pos="0 0.04 0.0005" quat="1.32679e-06 1 0 0" type="mesh" contype="0" conaffinity="0" group="1" rgba="0.372549 0.533333 1 1" mesh="finalcoupling" />
																		<geom pos="0 0.04 0.0005" quat="1.32679e-06 1 0 0" type="mesh" rgba="0.372549 0.533333 1 1" mesh="finalcoupling" />
																		<body name="finalend" pos="0.0005 0.06 0.0005" quat="0.706893 -0.0173635 0.706894 -0.0173635">
																			<inertial pos="-1.26318e-07 0.0305856 -0.00316821" quat="0.430889 0.561312 -0.56048 0.430262" mass="0.257835" diaginertia="0.000212339 0.000210588 0.000101027" />
																			<joint name="joint16" pos="0 0 0" axis="0 0 1" />
																			<geom pos="0 0 0.0306709" quat="9.38184e-07 -0.707105 0.707108 -9.38187e-07" type="mesh" contype="0" conaffinity="0" group="1" rgba="1 0.996078 0.968627 1" mesh="finalrod" />
																			<geom pos="0 0 0.0306709" quat="9.38184e-07 -0.707105 0.707108 -9.38187e-07" type="mesh" rgba="1 0.996078 0.968627 1" mesh="finalrod" />
																			<geom pos="-1.54268e-08 0.07 0.0005" quat="1.32679e-06 1 0 0" type="mesh" contype="0" conaffinity="0" group="1" rgba="0.458824 0.105882 0 1" mesh="finalend" />
																			<geom pos="-1.54268e-08 0.07 0.0005" quat="1.32679e-06 1 0 0" type="mesh" rgba="0.458824 0.105882 0 1" mesh="finalend" />
																		</body>
																	</body>
																</body>
															</body>
														</body>
													</body>
												</body>
											</body>
										</body>
									</body>
								</body>
							</body>
						</body>
					</body>
				</body>
			</body>
		</body>
	</worldbody>
	<actuator>
		<!-- FR leg -->
		<motor name="joint1_motor" joint="joint1" user="33" />
		<motor name="joint2_motor" joint="joint2" user="33" />
		<motor name="joint3_motor" joint="joint3" user="33" />
		<motor name="joint4_motor" joint="joint4" user="33" />
		<motor name="joint5_motor" joint="joint5" user="33" />
		<motor name="joint6_motor" joint="joint6" user="33" />
		<motor name="joint7_motor" joint="joint7" user="33" />
		<motor name="joint8_motor" joint="joint8" user="33" />
		<motor name="joint9_motor" joint="joint9" user="33" />
		<motor name="joint10_motor" joint="joint10" user="33" />
		<motor name="joint11_motor" joint="joint11" user="33" />
		<motor name="joint12_motor" joint="joint12" user="33" />
		<motor name="joint13_motor" joint="joint13" user="33" />
		<motor name="joint14_motor" joint="joint14" user="33" />
		<motor name="joint15_motor" joint="joint15" user="33" />
		<motor name="joint16_motor" joint="joint16" user="33" />
	</actuator>
</mujoco>
